Workbook
Name acct_early: 'Control & Parameters'!$C$52
Name acct_target: 'Control & Parameters'!$C$57
Name acq_month: 'Control & Parameters'!$C$91
Name acq_year1: 'Control & Parameters'!$C$67
Name acq_year2: 'Control & Parameters'!$C$68
Name acq_year3: 'Control & Parameters'!$C$69
Name admin_per_prop: 'Control & Parameters'!$C$60
Name avg_price: 'Control & Parameters'!$C$45
Name base_calendar_year: 'Control & Parameters'!$C$11
Name beq_baseline: 'Control & Parameters'!$C$37
Name beq_growth_mult: 'Control & Parameters'!$C$39
Name board_early: 'Control & Parameters'!$C$51
Name board_target: 'Control & Parameters'!$C$56
Name constrain_growth: 'Control & Parameters'!$C$89
Name conveyancing: 'Control & Parameters'!$C$47
Name cpi_general: 'Control & Parameters'!$C$8
Name cs_baseline_issue: 'Control & Parameters'!$C$32
Name cs_dividend_rate: 'Control & Parameters'!$C$28
Name cs_issue_cost_pct: 'Control & Parameters'!$C$31
Name cs_max_pct_capital: 'Control & Parameters'!$C$29
Name cs_takeup_mult: 'Control & Parameters'!$C$33
Name cs_withdrawal_rate: 'Control & Parameters'!$C$34
Name cs_withdrawal_years: 'Control & Parameters'!$C$30
Name ct_exempt_toggle: 'Control & Parameters'!$C$84
Name ct_rate: 'Control & Parameters'!$C$85
Name debt_pay_freq: 'Control & Parameters'!$C$92
Name div_month: 'Control & Parameters'!$C$93
Name fca_early: 'Control & Parameters'!$C$53
Name fca_target: 'Control & Parameters'!$C$58
Name founding_capital: 'Control & Parameters'!$C$38
Name gift_aid_rate: 'Control & Parameters'!$C$87
Name gift_aid_toggle: 'Control & Parameters'!$C$86
Name gift_baseline: 'Control & Parameters'!$C$36
Name gross_yield: 'Control & Parameters'!$C$41
Name hpi_premium: 'Control & Parameters'!$C$10
Name hpi_shock_pct: 'Control & Parameters'!$C$80
Name hpi_shock_year: 'Control & Parameters'!$C$79
Name ins_early: 'Control & Parameters'!$C$54
Name ins_target: 'Control & Parameters'!$C$59
Name lc_share: 'Control & Parameters'!$C$42
Name logistic_ceiling: 'Control & Parameters'!$C$72
Name logistic_dbl_yrs: 'Control & Parameters'!$C$73
Name logistic_floor: 'Control & Parameters'!$C$71
Name logistic_start_yr: 'Control & Parameters'!$C$70
Name maint_per_prop: 'Control & Parameters'!$C$76
Name min_cash_buffer: 'Control & Parameters'!$C$65
Name pf_coupon_spread: 'Control & Parameters'!$C$17
Name pf_fund_op_margin: 'Control & Parameters'!$C$15
Name pf_fund_reg_charge: 'Control & Parameters'!$C$16
Name pf_index_label: 'Control & Parameters'!$C$13
Name pf_invest_phase_yrs: 'Control & Parameters'!$C$19
Name pf_investor_rate: 'Control & Parameters'!$C$14
Name pf_ltv_limit: 'Control & Parameters'!$C$22
Name pf_max_raise: 'Control & Parameters'!$C$18
Name pf_refi_amort_yrs: 'Control & Parameters'!$C$26
Name pf_refi_rate: 'Control & Parameters'!$C$25
Name pf_refi_toggle: 'Control & Parameters'!$C$23
Name pf_refi_year: 'Control & Parameters'!$C$24
Name pf_release_rate: 'Control & Parameters'!$C$21
Name pf_release_start_yr: 'Control & Parameters'!$C$20

Sheet Control & Parameters
A1: STROUD LAND COMMONS — CONTROL & PARAMETERS
A2: Single source of truth. Blue = input. Green = scenario-selected live value referenced by every other sheet.
A3: Version 2.1 — closed-end Tontine annuity mechanics and independent-review remediation. Last updated 26 July 2026.
A4: SCENARIO (set on Dashboard) | C4: =Dashboard!$C$3 -> Base
A5: Scenario ID | C5: =MATCH($C$4,{"Base";"Optimistic";"Stress"},0) -> 1
A6: PARAMETER | B6: UNIT | C6: LIVE VALUE | E6: Base | F6: Optimistic | G6: Stress
A7: MACRO & INDEXATION
A8: General CPI inflation | B8: % p.a. | C8: =CHOOSE($C$5,E8,F8,G8) -> 0.025 | E8: 0.025 | F8: 0.02 | G8: 0.045
A9: Rent inflation | B9: % p.a. | C9: =CHOOSE($C$5,E9,F9,G9) -> 0.025 | E9: 0.025 | F9: 0.03 | G9: =$E9 -> 0.025
A10: HPI premium over CPI | B10: % p.a. | C10: =CHOOSE($C$5,E10,F10,G10) -> 0.01 | E10: 0.01 | F10: 0.02 | G10: =$E10 -> 0.01
A11: Base calendar year (Year 1) | B11: year | C11: =CHOOSE($C$5,E11,F11,G11) -> 2026 | E11: 2026 | F11: =$E11 -> 2026 | G11: =$E11 -> 2026
A12: TONTINE FUND — CLOSED-END LIFETIME ANNUITY MUTUAL
A13: Indexation basis (principal and coupon) | B13: text | C13: =CHOOSE($C$5,E13,F13,G13) -> CPI | E13: CPI | F13: =$E13 -> CPI | G13: =$E13 -> CPI
A14: Target investor annuity rate — spread over index | B14: % p.a. | C14: =CHOOSE($C$5,E14,F14,G14) -> 0.03 | E14: 0.03 | F14: 0.03 | G14: 0.03
A15: Fund operating cost margin | B15: % p.a. | C15: =CHOOSE($C$5,E15,F15,G15) -> 0.005 | E15: 0.005 | F15: =$E15 -> 0.005 | G15: =$E15 -> 0.005
A16: Fund regulatory capital charge | B16: % p.a. | C16: =CHOOSE($C$5,E16,F16,G16) -> 0.0025 | E16: 0.0025 | F16: =$E16 -> 0.0025 | G16: =$E16 -> 0.0025
A17: Implied SLC coupon — spread over index (derived) | B17: % p.a. | C17: =CHOOSE($C$5,E17,F17,G17) -> 0.0375 | E17: =SUM(E14:E16) -> 0.0375 | F17: =SUM(F14:F16) -> 0.0375 | G17: =SUM(G14:G16) -> 0.0375
A18: Tontine maximum raise | B18: £ | C18: =CHOOSE($C$5,E18,F18,G18) -> 50000000 | E18: 50000000 | F18: =$E18 -> 50000000 | G18: =$E18 -> 50000000
A19: Investment phase duration | B19: years | C19: =CHOOSE($C$5,E19,F19,G19) -> 10 | E19: 10 | F19: =$E19 -> 10 | G19: =$E19 -> 10
A20: Release phase start year | B20: model year | C20: =CHOOSE($C$5,E20,F20,G20) -> 25 | E20: 25 | F20: =$E20 -> 25 | G20: =$E20 -> 25
A21: Annual release rate | B21: % of outstanding balance p.a. | C21: =CHOOSE($C$5,E21,F21,G21) -> 0.06 | E21: 0.06 | F21: =$E21 -> 0.06 | G21: =$E21 -> 0.06
A22: LTV limit | B22: % of portfolio value | C22: =CHOOSE($C$5,E22,F22,G22) -> 0.7 | E22: 0.7 | F22: 0.75 | G22: =$E22 -> 0.7
A23: Refinance into commercial mortgage? (1 = Yes) | B23: 1 / 0 | C23: =CHOOSE($C$5,E23,F23,G23) -> 0 | E23: 0 | F23: =$E23 -> 0 | G23: =$E23 -> 0
A24: Refinancing year | B24: model year | C24: =CHOOSE($C$5,E24,F24,G24) -> 26 | E24: 26 | F24: =$E24 -> 26 | G24: =$E24 -> 26
A25: Commercial mortgage rate | B25: % p.a. | C25: =CHOOSE($C$5,E25,F25,G25) -> 0.055 | E25: 0.055 | F25: 0.045 | G25: =$E25 -> 0.055
A26: Commercial mortgage amortisation | B26: years | C26: =CHOOSE($C$5,E26,F26,G26) -> 25 | E26: 25 | F26: =$E26 -> 25 | G26: =$E26 -> 25
A27: COMMUNITY SHARES (JUNIOR DEBT)
A28: Default dividend rate (override per year on Capital & Debt) | B28: % p.a. | C28: =CHOOSE($C$5,E28,F28,G28) -> 0.03 | E28: 0.03 | F28: =$E28 -> 0.03 | G28: =$E28 -> 0.03
A29: Maximum issuance cap | B29: % of total capital | C29: =CHOOSE($C$5,E29,F29,G29) -> 0.2 | E29: 0.2 | F29: =$E29 -> 0.2 | G29: =$E29 -> 0.2
A30: Withdrawal restriction period | B30: years | C30: =CHOOSE($C$5,E30,F30,G30) -> 5 | E30: 5 | F30: =$E30 -> 5 | G30: =$E30 -> 5
A31: Issuance / marketing cost | B31: % of proceeds | C31: =CHOOSE($C$5,E31,F31,G31) -> 0.05 | E31: 0.05 | F31: 0.04 | G31: =$E31 -> 0.05
A32: Baseline annual issuance (real) | B32: £ p.a. | C32: =CHOOSE($C$5,E32,F32,G32) -> 250000 | E32: 250000 | F32: =$E32 -> 250000 | G32: =$E32 -> 250000
A33: Take-up multiplier | B33: x | C33: =CHOOSE($C$5,E33,F33,G33) -> 1 | E33: 1 | F33: 1.5 | G33: 0.5
A34: Annual withdrawal rate on eligible shares | B34: % p.a. | C34: =CHOOSE($C$5,E34,F34,G34) -> 0.02 | E34: 0.02 | F34: 0.01 | G34: =$E34 -> 0.02
A35: BEQUESTS & GIFTS
A36: Cash gifts from living donors (Gift Aid eligible) | B36: £ p.a. | C36: =CHOOSE($C$5,E36,F36,G36) -> 40000 | E36: 40000 | F36: 60000 | G36: =$E36 -> 40000
A37: Bequests from estates (not Gift Aid eligible) | B37: £ p.a. | C37: =CHOOSE($C$5,E37,F37,G37) -> 60000 | E37: 60000 | F37: 90000 | G37: =$E37 -> 60000
A38: Founding capital injection (Year 1 only) | B38: £ | C38: =CHOOSE($C$5,E38,F38,G38) -> 150000 | E38: 150000 | F38: =$E38 -> 150000 | G38: =$E38 -> 150000
A39: Real growth multiplier | B39: % p.a. | C39: =CHOOSE($C$5,E39,F39,G39) -> 0 | E39: 0 | F39: 0.02 | G39: =$E39 -> 0
A40: RENT & YIELD
...

Sheet Sheet2

Sheet Scenarios
A1: STROUD LAND COMMONS — SCENARIO DEFINITIONS
A2: LIVE MIRROR — every cell below is a formula reading Control & Parameters. Nothing here is an input and nothing here drives the model. To change an assumption, edit the Base, Optimistic or Stress column on Control & Parameters.
A4: Stress scenario per brief: void rate +10pts (15%), CPI +2pts (4.5%), community share take-up halved, a one-off −20% HPI shock in Year 5, and rent growth held at 0% for the two years following that shock.
A6: PARAMETER | B6: UNIT | C6: BASE | D6: OPTIMISTIC | E6: STRESS
A7: =IF('Control & Parameters'!A7="","",'Control & Parameters'!A7) -> MACRO & INDEXATION | B7: =IF('Control & Parameters'!B7="","",'Control & Parameters'!B7) | C7: =IF('Control & Parameters'!E7="","",'Control & Parameters'!E7) | D7: =IF('Control & Parameters'!F7="","",'Control & Parameters'!F7) | E7: =IF('Control & Parameters'!G7="","",'Control & Parameters'!G7)
A8: =IF('Control & Parameters'!A8="","",'Control & Parameters'!A8) -> General CPI inflation | B8: =IF('Control & Parameters'!B8="","",'Control & Parameters'!B8) -> % p.a. | C8: =IF('Control & Parameters'!E8="","",'Control & Parameters'!E8) -> 0.025 | D8: =IF('Control & Parameters'!F8="","",'Control & Parameters'!F8) -> 0.02 | E8: =IF('Control & Parameters'!G8="","",'Control & Parameters'!G8) -> 0.045
A9: =IF('Control & Parameters'!A9="","",'Control & Parameters'!A9) -> Rent inflation | B9: =IF('Control & Parameters'!B9="","",'Control & Parameters'!B9) -> % p.a. | C9: =IF('Control & Parameters'!E9="","",'Control & Parameters'!E9) -> 0.025 | D9: =IF('Control & Parameters'!F9="","",'Control & Parameters'!F9) -> 0.03 | E9: =IF('Control & Parameters'!G9="","",'Control & Parameters'!G9) -> 0.025
A10: =IF('Control & Parameters'!A10="","",'Control & Parameters'!A10) -> HPI premium over CPI | B10: =IF('Control & Parameters'!B10="","",'Control & Parameters'!B10) -> % p.a. | C10: =IF('Control & Parameters'!E10="","",'Control & Parameters'!E10) -> 0.01 | D10: =IF('Control & Parameters'!F10="","",'Control & Parameters'!F10) -> 0.02 | E10: =IF('Control & Parameters'!G10="","",'Control & Parameters'!G10) -> 0.01
A11: =IF('Control & Parameters'!A11="","",'Control & Parameters'!A11) -> Base calendar year (Year 1) | B11: =IF('Control & Parameters'!B11="","",'Control & Parameters'!B11) -> year | C11: =IF('Control & Parameters'!E11="","",'Control & Parameters'!E11) -> 2026 | D11: =IF('Control & Parameters'!F11="","",'Control & Parameters'!F11) -> 2026 | E11: =IF('Control & Parameters'!G11="","",'Control & Parameters'!G11) -> 2026
A12: =IF('Control & Parameters'!A12="","",'Control & Parameters'!A12) -> TONTINE FUND — CLOSED-END LIFETIME ANNUITY MUTUAL | B12: =IF('Control & Parameters'!B12="","",'Control & Parameters'!B12) | C12: =IF('Control & Parameters'!E12="","",'Control & Parameters'!E12) | D12: =IF('Control & Parameters'!F12="","",'Control & Parameters'!F12) | E12: =IF('Control & Parameters'!G12="","",'Control & Parameters'!G12)
A13: =IF('Control & Parameters'!A13="","",'Control & Parameters'!A13) -> Indexation basis (principal and coupon) | B13: =IF('Control & Parameters'!B13="","",'Control & Parameters'!B13) -> text | C13: =IF('Control & Parameters'!E13="","",'Control & Parameters'!E13) -> CPI | D13: =IF('Control & Parameters'!F13="","",'Control & Parameters'!F13) -> CPI | E13: =IF('Control & Parameters'!G13="","",'Control & Parameters'!G13) -> CPI
A14: =IF('Control & Parameters'!A14="","",'Control & Parameters'!A14) -> Target investor annuity rate — spread over index | B14: =IF('Control & Parameters'!B14="","",'Control & Parameters'!B14) -> % p.a. | C14: =IF('Control & Parameters'!E14="","",'Control & Parameters'!E14) -> 0.03 | D14: =IF('Control & Parameters'!F14="","",'Control & Parameters'!F14) -> 0.03 | E14: =IF('Control & Parameters'!G14="","",'Control & Parameters'!G14) -> 0.03
A15: =IF('Control & Parameters'!A15="","",'Control & Parameters'!A15) -> Fund operating cost margin | B15: =IF('Control & Parameters'!B15="","",'Control & Parameters'!B15) -> % p.a. | C15: =IF('Control & Parameters'!E15="","",'Control & Parameters'!E15) -> 0.005 | D15: =IF('Control & Parameters'!F15="","",'Control & Parameters'!F15) -> 0.005 | E15: =IF('Control & Parameters'!G15="","",'Control & Parameters'!G15) -> 0.005
A16: =IF('Control & Parameters'!A16="","",'Control & Parameters'!A16) -> Fund regulatory capital charge | B16: =IF('Control & Parameters'!B16="","",'Control & Parameters'!B16) -> % p.a. | C16: =IF('Control & Parameters'!E16="","",'Control & Parameters'!E16) -> 0.0025 | D16: =IF('Control & Parameters'!F16="","",'Control & Parameters'!F16) -> 0.0025 | E16: =IF('Control & Parameters'!G16="","",'Control & Parameters'!G16) -> 0.0025
A17: =IF('Control & Parameters'!A17="","",'Control & Parameters'!A17) -> Implied SLC coupon — spread over index (derived) | B17: =IF('Control & Parameters'!B17="","",'Control & Parameters'!B17) -> % p.a. | C17: =IF('Control & Parameters'!E17="","",'Control & Parameters'!E17) -> 0.0375 | D17: =IF('Control & Parameters'!F17="","",'Control & Parameters'!F17) -> 0.0375 | E17: =IF('Control & Parameters'!G17="","",'Control & Parameters'!G17) -> 0.0375
A18: =IF('Control & Parameters'!A18="","",'Control & Parameters'!A18) -> Tontine maximum raise | B18: =IF('Control & Parameters'!B18="","",'Control & Parameters'!B18) -> £ | C18: =IF('Control & Parameters'!E18="","",'Control & Parameters'!E18) -> 50000000 | D18: =IF('Control & Parameters'!F18="","",'Control & Parameters'!F18) -> 50000000 | E18: =IF('Control & Parameters'!G18="","",'Control & Parameters'!G18) -> 50000000
... A93: =IF('Control & Parameters'!A93="","",'Control & Parameters'!A93) -> Month in year when dividends are paid | B93: =IF('Control & Parameters'!B93="","",'Control & Parameters'!B93) -> month (1–12) | C93: =IF('Control & Parameters'!E93="","",'Control & Parameters'!E93) -> 12 | D93: =IF('Control & Parameters'!F93="","",'Control & Parameters'!F93) -> 12 | E93: =IF('Control & Parameters'!G93="","",'Control & Parameters'!G93) -> 12

Sheet Macro & Indexation
A1: MACRO & INDEXATION
A2: All index series start at 1.00 in Year 1. HPI = CPI + premium, plus one-off shock, with a manual override row.
A6: Model year | D6: 1 | E6: 2 | F6: 3 | G6: 4 | H6: 5 | I6: 6 | J6: 7 | K6: 8 | L6: 9 | M6: 10 | N6: 11 | O6: 12 | P6: 13 | Q6: 14 | R6: 15 | S6: 16 | T6: 17 | U6: 18 | V6: 19 | W6: 20 | X6: 21 | Y6: 22 | Z6: 23 | AA6: 24 | AB6: 25 | AC6: 26 | AD6: 27 | AE6: 28 | AF6: 29 | AG6: 30 | AH6: 31 | AI6: 32 | AJ6: 33 | AK6: 34 | AL6: 35 | AM6: 36 | AN6: 37 | AO6: 38 | AP6: 39 | AQ6: 40 | AR6: 41 | AS6: 42 | AT6: 43 | AU6: 44 | AV6: 45 | AW6: 46 | AX6: 47 | AY6: 48 | AZ6: 49 | BA6: 50
A7: Calendar year | D7: =base_calendar_year+D$6-1 -> 2026 | E7: =base_calendar_year+E$6-1 -> 2027 | F7: =base_calendar_year+F$6-1 -> 2028 | G7: =base_calendar_year+G$6-1 -> 2029 | H7: =base_calendar_year+H$6-1 -> 2030 | I7: =base_calendar_year+I$6-1 -> 2031 | J7: =base_calendar_year+J$6-1 -> 2032 | K7: =base_calendar_year+K$6-1 -> 2033 | ... BA7: =base_calendar_year+BA$6-1 -> 2075
A9: General CPI inflation | B9: % p.a. | D9: =cpi_general -> 0.025 | E9: =cpi_general -> 0.025 | F9: =cpi_general -> 0.025 | G9: =cpi_general -> 0.025 | H9: =cpi_general -> 0.025 | I9: =cpi_general -> 0.025 | J9: =cpi_general -> 0.025 | K9: =cpi_general -> 0.025 | ... BA9: =cpi_general -> 0.025
A10: CPI index | B10: Year 1 = 1.00 | D10: =IF(D$6=1,1,C10*(1+D9)) -> 1 | E10: =IF(E$6=1,1,D10*(1+E9)) -> 1.025 | F10: =IF(F$6=1,1,E10*(1+F9)) -> 1.050625 | G10: =IF(G$6=1,1,F10*(1+G9)) -> 1.0768906 | H10: =IF(H$6=1,1,G10*(1+H9)) -> 1.1038129 | I10: =IF(I$6=1,1,H10*(1+I9)) -> 1.1314082 | J10: =IF(J$6=1,1,I10*(1+J9)) -> 1.1596934 | K10: =IF(K$6=1,1,J10*(1+K9)) -> 1.1886858 | ... BA10: =IF(BA$6=1,1,AZ10*(1+BA9)) -> 3.3532768
A11: Rent inflation (shock-adjusted) | B11: % p.a. | D11: =IF(AND(rent_shock_years>0,hpi_shock_year>0,D$6>=hpi_shock_year,D$6<hpi_shock_year+rent_shock_years),rent_shock_rate,rent_inflation) -> 0.025 | E11: =IF(AND(rent_shock_years>0,hpi_shock_year>0,E$6>=hpi_shock_year,E$6<hpi_shock_year+rent_shock_years),rent_shock_rate,rent_inflation) -> 0.025 | F11: =IF(AND(rent_shock_years>0,hpi_shock_year>0,F$6>=hpi_shock_year,F$6<hpi_shock_year+rent_shock_years),rent_shock_rate,rent_inflation) -> 0.025 | G11: =IF(AND(rent_shock_years>0,hpi_shock_year>0,G$6>=hpi_shock_year,G$6<hpi_shock_year+rent_shock_years),rent_shock_rate,rent_inflation) -> 0.025 | H11: =IF(AND(rent_shock_years>0,hpi_shock_year>0,H$6>=hpi_shock_year,H$6<hpi_shock_year+rent_shock_years),rent_shock_rate,rent_inflation) -> 0.025 | I11: =IF(AND(rent_shock_years>0,hpi_shock_year>0,I$6>=hpi_shock_year,I$6<hpi_shock_year+rent_shock_years),rent_shock_rate,rent_inflation) -> 0.025 | J11: =IF(AND(rent_shock_years>0,hpi_shock_year>0,J$6>=hpi_shock_year,J$6<hpi_shock_year+rent_shock_years),rent_shock_rate,rent_inflation) -> 0.025 | K11: =IF(AND(rent_shock_years>0,hpi_shock_year>0,K$6>=hpi_shock_year,K$6<hpi_shock_year+rent_shock_years),rent_shock_rate,rent_inflation) -> 0.025 | ... BA11: =IF(AND(rent_shock_years>0,hpi_shock_year>0,BA$6>=hpi_shock_year,BA$6<hpi_shock_year+rent_shock_years),rent_shock_rate,rent_inflation) -> 0.025
A12: Rent index | B12: Year 1 = 1.00 | D12: =IF(D$6=1,1,C12*(1+D11)) -> 1 | E12: =IF(E$6=1,1,D12*(1+E11)) -> 1.025 | F12: =IF(F$6=1,1,E12*(1+F11)) -> 1.050625 | G12: =IF(G$6=1,1,F12*(1+G11)) -> 1.0768906 | H12: =IF(H$6=1,1,G12*(1+H11)) -> 1.1038129 | I12: =IF(I$6=1,1,H12*(1+I11)) -> 1.1314082 | J12: =IF(J$6=1,1,I12*(1+J11)) -> 1.1596934 | K12: =IF(K$6=1,1,J12*(1+K11)) -> 1.1886858 | ... BA12: =IF(BA$6=1,1,AZ12*(1+BA11)) -> 3.3532768
A13: HPI — base rate | B13: CPI + premium | D13: =cpi_general+hpi_premium -> 0.035 | E13: =cpi_general+hpi_premium -> 0.035 | F13: =cpi_general+hpi_premium -> 0.035 | G13: =cpi_general+hpi_premium -> 0.035 | H13: =cpi_general+hpi_premium -> 0.035 | I13: =cpi_general+hpi_premium -> 0.035 | J13: =cpi_general+hpi_premium -> 0.035 | K13: =cpi_general+hpi_premium -> 0.035 | ... BA13: =cpi_general+hpi_premium -> 0.035
A14: HPI — parameterised one-off shock | B14: from Control | D14: =IF(AND(hpi_shock_year>0,D$6=hpi_shock_year),hpi_shock_pct,0) -> 0 | E14: =IF(AND(hpi_shock_year>0,E$6=hpi_shock_year),hpi_shock_pct,0) -> 0 | F14: =IF(AND(hpi_shock_year>0,F$6=hpi_shock_year),hpi_shock_pct,0) -> 0 | G14: =IF(AND(hpi_shock_year>0,G$6=hpi_shock_year),hpi_shock_pct,0) -> 0 | H14: =IF(AND(hpi_shock_year>0,H$6=hpi_shock_year),hpi_shock_pct,0) -> 0 | I14: =IF(AND(hpi_shock_year>0,I$6=hpi_shock_year),hpi_shock_pct,0) -> 0 | J14: =IF(AND(hpi_shock_year>0,J$6=hpi_shock_year),hpi_shock_pct,0) -> 0 | K14: =IF(AND(hpi_shock_year>0,K$6=hpi_shock_year),hpi_shock_pct,0) -> 0 | ... BA14: =IF(AND(hpi_shock_year>0,BA$6=hpi_shock_year),hpi_shock_pct,0) -> 0
A15: HPI — manual override (blank = use above) | B15: INPUT
A16: HPI — effective rate | B16: % p.a. | D16: =IF(D15<>"",D15,D13+D14) -> 0.035 | E16: =IF(E15<>"",E15,E13+E14) -> 0.035 | F16: =IF(F15<>"",F15,F13+F14) -> 0.035 | G16: =IF(G15<>"",G15,G13+G14) -> 0.035 | H16: =IF(H15<>"",H15,H13+H14) -> 0.035 | I16: =IF(I15<>"",I15,I13+I14) -> 0.035 | J16: =IF(J15<>"",J15,J13+J14) -> 0.035 | K16: =IF(K15<>"",K15,K13+K14) -> 0.035 | ... BA16: =IF(BA15<>"",BA15,BA13+BA14) -> 0.035
A17: House price index (HPI) | B17: Year 1 = 1.00 | D17: =IF(D$6=1,1,C17*(1+D16)) -> 1 | E17: =IF(E$6=1,1,D17*(1+E16)) -> 1.035 | F17: =IF(F$6=1,1,E17*(1+F16)) -> 1.071225 | G17: =IF(G$6=1,1,F17*(1+G16)) -> 1.1087179 | H17: =IF(H$6=1,1,G17*(1+H16)) -> 1.147523 | I17: =IF(I$6=1,1,H17*(1+I16)) -> 1.1876863 | J17: =IF(J$6=1,1,I17*(1+J16)) -> 1.2292553 | K17: =IF(K$6=1,1,J17*(1+K16)) -> 1.2722793 | ... BA17: =IF(BA$6=1,1,AZ17*(1+BA16)) -> 5.3960646
A19: Average property price (indexed) | B19: £ | D19: =avg_price*D17 -> 280000 | E19: =avg_price*E17 -> 289800 | F19: =avg_price*F17 -> 299943 | G19: =avg_price*G17 -> 310441 | H19: =avg_price*H17 -> 321306.44 | I19: =avg_price*I17 -> 332552.17 | J19: =avg_price*J17 -> 344191.49 | K19: =avg_price*K17 -> 356238.19 | ... BA19: =avg_price*BA17 -> 1510898.1
A20: Cost inflation index | B20: CPI index | D20: =D10 -> 1 | E20: =E10 -> 1.025 | F20: =F10 -> 1.050625 | G20: =G10 -> 1.0768906 | H20: =H10 -> 1.1038129 | I20: =I10 -> 1.1314082 | J20: =J10 -> 1.1596934 | K20: =K10 -> 1.1886858 | ... BA20: =BA10 -> 3.3532768

Sheet Growth Engine
A1: GROWTH ENGINE — ACQUISITIONS & ADMIN COST SCALING
A2: Years 1-3: absolute acquisitions. Year 4+: logistic S-curve on the cumulative portfolio (floor / ceiling / doubling rate).
A4: Logistic intrinsic growth rate r = LN(2) / doubling years | B4: r | C4: =LN(2)/logistic_dbl_yrs -> 0.1732868
A6: Model year | D6: 1 | E6: 2 | F6: 3 | G6: 4 | H6: 5 | I6: 6 | J6: 7 | K6: 8 | L6: 9 | M6: 10 | N6: 11 | O6: 12 | P6: 13 | Q6: 14 | R6: 15 | S6: 16 | T6: 17 | U6: 18 | V6: 19 | W6: 20 | X6: 21 | Y6: 22 | Z6: 23 | AA6: 24 | AB6: 25 | AC6: 26 | AD6: 27 | AE6: 28 | AF6: 29 | AG6: 30 | AH6: 31 | AI6: 32 | AJ6: 33 | AK6: 34 | AL6: 35 | AM6: 36 | AN6: 37 | AO6: 38 | AP6: 39 | AQ6: 40 | AR6: 41 | AS6: 42 | AT6: 43 | AU6: 44 | AV6: 45 | AW6: 46 | AX6: 47 | AY6: 48 | AZ6: 49 | BA6: 50
A7: Calendar year | D7: =base_calendar_year+D$6-1 -> 2026 | E7: =base_calendar_year+E$6-1 -> 2027 | F7: =base_calendar_year+F$6-1 -> 2028 | G7: =base_calendar_year+G$6-1 -> 2029 | H7: =base_calendar_year+H$6-1 -> 2030 | I7: =base_calendar_year+I$6-1 -> 2031 | J7: =base_calendar_year+J$6-1 -> 2032 | K7: =base_calendar_year+K$6-1 -> 2033 | ... BA7: =base_calendar_year+BA$6-1 -> 2075
A9: Portfolio — opening | B9: properties | D9: =0 -> 0 | E9: =D11 -> 1 | F9: =E11 -> 3 | G9: =F11 -> 6 | H9: =G11 -> 9 | I9: =H11 -> 12 | J9: =I11 -> 15 | K9: =J11 -> 18 | L9: =K11 -> 21 | ... BA9: =AZ11 -> 48
A10: Properties acquired in year | B10: properties | D10: =MIN(D26,D25) -> 1 | E10: =MIN(E26,E25) -> 2 | F10: =MIN(F26,F25) -> 3 | G10: =MIN(G26,G25) -> 3 | H10: =MIN(H26,H25) -> 3 | I10: =MIN(I26,I25) -> 3 | J10: =MIN(J26,J25) -> 3 | K10: =MIN(K26,K25) -> 3 | ... BA10: =MIN(BA26,BA25) -> 1
A11: Portfolio — closing | B11: properties | D11: =D9+D10 -> 1 | E11: =E9+E10 -> 3 | F11: =F9+F10 -> 6 | G11: =G9+G10 -> 9 | H11: =H9+H10 -> 12 | I11: =I9+I10 -> 15 | J11: =J9+J10 -> 18 | K11: =K9+K10 -> 21 | ... BA11: =BA9+BA10 -> 49
A13: ADMIN COST SCALING
A14: Ramp factor (early → target) | B14: 0 = early, 1 = target | D14: =MIN(1,MAX(0,(D$6-1)/MAX(1,logistic_start_yr-1))) -> 0 | E14: =MIN(1,MAX(0,(E$6-1)/MAX(1,logistic_start_yr-1))) -> 0.33333333 | F14: =MIN(1,MAX(0,(F$6-1)/MAX(1,logistic_start_yr-1))) -> 0.66666667 | G14: =MIN(1,MAX(0,(G$6-1)/MAX(1,logistic_start_yr-1))) -> 1 | H14: =MIN(1,MAX(0,(H$6-1)/MAX(1,logistic_start_yr-1))) -> 1 | I14: =MIN(1,MAX(0,(I$6-1)/MAX(1,logistic_start_yr-1))) -> 1 | J14: =MIN(1,MAX(0,(J$6-1)/MAX(1,logistic_start_yr-1))) -> 1 | K14: =MIN(1,MAX(0,(K$6-1)/MAX(1,logistic_start_yr-1))) -> 1 | ... BA14: =MIN(1,MAX(0,(BA$6-1)/MAX(1,logistic_start_yr-1))) -> 1
A15: Board remuneration | B15: £ | D15: =(board_early+D$14*(board_target-board_early))*'Macro & Indexation'!D$20 -> 0 | E15: =(board_early+E$14*(board_target-board_early))*'Macro & Indexation'!E$20 -> 4100 | F15: =(board_early+F$14*(board_target-board_early))*'Macro & Indexation'!F$20 -> 8405 | G15: =(board_early+G$14*(board_target-board_early))*'Macro & Indexation'!G$20 -> 12922.687 | H15: =(board_early+H$14*(board_target-board_early))*'Macro & Indexation'!H$20 -> 13245.755 | I15: =(board_early+I$14*(board_target-board_early))*'Macro & Indexation'!I$20 -> 13576.899 | J15: =(board_early+J$14*(board_target-board_early))*'Macro & Indexation'!J$20 -> 13916.321 | K15: =(board_early+K$14*(board_target-board_early))*'Macro & Indexation'!K$20 -> 14264.229 | ... BA15: =(board_early+BA$14*(board_target-board_early))*'Macro & Indexation'!BA$20 -> 40239.322
A16: Accounting & audit | B16: £ | D16: =(acct_early+D$14*(acct_target-acct_early))*'Macro & Indexation'!D$20 -> 3000 | E16: =(acct_early+E$14*(acct_target-acct_early))*'Macro & Indexation'!E$20 -> 4783.3333 | F16: =(acct_early+F$14*(acct_target-acct_early))*'Macro & Indexation'!F$20 -> 6653.9583 | G16: =(acct_early+G$14*(acct_target-acct_early))*'Macro & Indexation'!G$20 -> 8615.125 | H16: =(acct_early+H$14*(acct_target-acct_early))*'Macro & Indexation'!H$20 -> 8830.5031 | I16: =(acct_early+I$14*(acct_target-acct_early))*'Macro & Indexation'!I$20 -> 9051.2657 | J16: =(acct_early+J$14*(acct_target-acct_early))*'Macro & Indexation'!J$20 -> 9277.5473 | K16: =(acct_early+K$14*(acct_target-acct_early))*'Macro & Indexation'!K$20 -> 9509.486 | ... BA16: =(acct_early+BA$14*(acct_target-acct_early))*'Macro & Indexation'!BA$20 -> 26826.214
A17: FCA & annual reporting | B17: £ | D17: =(fca_early+D$14*(fca_target-fca_early))*'Macro & Indexation'!D$20 -> 1500 | E17: =(fca_early+E$14*(fca_target-fca_early))*'Macro & Indexation'!E$20 -> 2050 | F17: =(fca_early+F$14*(fca_target-fca_early))*'Macro & Indexation'!F$20 -> 2626.5625 | G17: =(fca_early+G$14*(fca_target-fca_early))*'Macro & Indexation'!G$20 -> 3230.6719 | H17: =(fca_early+H$14*(fca_target-fca_early))*'Macro & Indexation'!H$20 -> 3311.4387 | I17: =(fca_early+I$14*(fca_target-fca_early))*'Macro & Indexation'!I$20 -> 3394.2246 | J17: =(fca_early+J$14*(fca_target-fca_early))*'Macro & Indexation'!J$20 -> 3479.0803 | K17: =(fca_early+K$14*(fca_target-fca_early))*'Macro & Indexation'!K$20 -> 3566.0573 | ... BA17: =(fca_early+BA$14*(fca_target-fca_early))*'Macro & Indexation'!BA$20 -> 10059.83
A18: Insurance | B18: £ | D18: =(ins_early+D$14*(ins_target-ins_early))*'Macro & Indexation'!D$20 -> 1000 | E18: =(ins_early+E$14*(ins_target-ins_early))*'Macro & Indexation'!E$20 -> 1366.6667 | F18: =(ins_early+F$14*(ins_target-ins_early))*'Macro & Indexation'!F$20 -> 1751.0417 | G18: =(ins_early+G$14*(ins_target-ins_early))*'Macro & Indexation'!G$20 -> 2153.7812 | H18: =(ins_early+H$14*(ins_target-ins_early))*'Macro & Indexation'!H$20 -> 2207.6258 | I18: =(ins_early+I$14*(ins_target-ins_early))*'Macro & Indexation'!I$20 -> 2262.8164 | J18: =(ins_early+J$14*(ins_target-ins_early))*'Macro & Indexation'!J$20 -> 2319.3868 | K18: =(ins_early+K$14*(ins_target-ins_early))*'Macro & Indexation'!K$20 -> 2377.3715 | ... BA18: =(ins_early+BA$14*(ins_target-ins_early))*'Macro & Indexation'!BA$20 -> 6706.5536
A19: Variable admin (per property) | B19: £ | D19: =admin_per_prop*D11*'Macro & Indexation'!D$20 -> 150 | E19: =admin_per_prop*E11*'Macro & Indexation'!E$20 -> 461.25 | F19: =admin_per_prop*F11*'Macro & Indexation'!F$20 -> 945.5625 | G19: =admin_per_prop*G11*'Macro & Indexation'!G$20 -> 1453.8023 | H19: =admin_per_prop*H11*'Macro & Indexation'!H$20 -> 1986.8632 | I19: =admin_per_prop*I11*'Macro & Indexation'!I$20 -> 2545.6685 | J19: =admin_per_prop*J11*'Macro & Indexation'!J$20 -> 3131.1722 | K19: =admin_per_prop*K11*'Macro & Indexation'!K$20 -> 3744.3601 | ... BA19: =admin_per_prop*BA11*'Macro & Indexation'!BA$20 -> 24646.584
A20: Total admin costs | B20: £ | D20: =SUM(D15:D19) -> 5650 | E20: =SUM(E15:E19) -> 12761.25 | F20: =SUM(F15:F19) -> 20382.125 | G20: =SUM(G15:G19) -> 28376.068 | H20: =SUM(H15:H19) -> 29582.185 | I20: =SUM(I15:I19) -> 30830.874 | J20: =SUM(J15:J19) -> 32123.508 | K20: =SUM(K15:K19) -> 33461.504 | ... BA20: =SUM(BA15:BA19) -> 108478.5
A22: FUNDING-CONSTRAINED ACQUISITION CAP
A23: Unit acquisition cost (price + SDLT + fees + retrofit) | B23: £ | D23: ='Macro & Indexation'!D19*(1+sdlt_rate)+(conveyancing+survey_cost+retrofit_cost)*'Macro & Indexation'!D20 -> 288300 | E23: ='Macro & Indexation'!E19*(1+sdlt_rate)+(conveyancing+survey_cost+retrofit_cost)*'Macro & Indexation'!E20 -> 298307.5 | F23: ='Macro & Indexation'!F19*(1+sdlt_rate)+(conveyancing+survey_cost+retrofit_cost)*'Macro & Indexation'!F20 -> 308663.19 | G23: ='Macro & Indexation'!G19*(1+sdlt_rate)+(conveyancing+survey_cost+retrofit_cost)*'Macro & Indexation'!G20 -> 319379.2 | H23: ='Macro & Indexation'!H19*(1+sdlt_rate)+(conveyancing+survey_cost+retrofit_cost)*'Macro & Indexation'!H20 -> 330468.09 | I23: ='Macro & Indexation'!I19*(1+sdlt_rate)+(conveyancing+survey_cost+retrofit_cost)*'Macro & Indexation'!I20 -> 341942.85 | J23: ='Macro & Indexation'!J19*(1+sdlt_rate)+(conveyancing+survey_cost+retrofit_cost)*'Macro & Indexation'!J20 -> 353816.95 | K23: ='Macro & Indexation'!K19*(1+sdlt_rate)+(conveyancing+survey_cost+retrofit_cost)*'Macro & Indexation'!K20 -> 366104.29 | ... BA23: ='Macro & Indexation'!BA19*(1+sdlt_rate)+(conveyancing+survey_cost+retrofit_cost)*'Macro & Indexation'!BA20 -> 1538730.3
A24: Funding capacity excl. new gearing on purchases | B24: £ | D24: =D27*MIN(MAX(0,pf_ltv_limit*'Asset Register'!C61-'Capital & Debt'!C43-'Capital & Debt'!C50),MAX(0,pf_max_raise-'Capital & Debt'!C38))+MAX(0,'Financial Statements'!C65-MAX('Capital & Debt'!C60,min_cash_buffer))+'Capital & Debt'!D14+'Capital & Debt'!D22+'Capital & Debt'!D24+'Capital & Debt'!D25 -> 260000 | E24: =E27*MIN(MAX(0,pf_ltv_limit*'Asset Register'!D61-'Capital & Debt'!D43-'Capital & Debt'!D50),MAX(0,pf_max_raise-'Capital & Debt'!D38))+MAX(0,'Financial Statements'!D65-MAX('Capital & Debt'!D60,min_cash_buffer))+'Capital & Debt'!E14+'Capital & Debt'!E22+'Capital & Debt'!E24+'Capital & Debt'!E25 -> 330335.16 | F24: =F27*MIN(MAX(0,pf_ltv_limit*'Asset Register'!E61-'Capital & Debt'!E43-'Capital & Debt'!E50),MAX(0,pf_max_raise-'Capital & Debt'!E38))+MAX(0,'Financial Statements'!E65-MAX('Capital & Debt'!E60,min_cash_buffer))+'Capital & Debt'!F14+'Capital & Debt'!F22+'Capital & Debt'!F24+'Capital & Debt'!F25 -> 381977.76 | G24: =G27*MIN(MAX(0,pf_ltv_limit*'Asset Register'!F61-'Capital & Debt'!F43-'Capital & Debt'!F50),MAX(0,pf_max_raise-'Capital & Debt'!F38))+MAX(0,'Financial Statements'!F65-MAX('Capital & Debt'!F60,min_cash_buffer))+'Capital & Debt'!G14+'Capital & Debt'!G22+'Capital & Debt'!G24+'Capital & Debt'!G25 -> 400774.68 | H24: =H27*MIN(MAX(0,pf_ltv_limit*'Asset Register'!G61-'Capital & Debt'!G43-'Capital & Debt'!G50),MAX(0,pf_max_raise-'Capital & Debt'!G38))+MAX(0,'Financial Statements'!G65-MAX('Capital & Debt'!G60,min_cash_buffer))+'Capital & Debt'!H14+'Capital & Debt'!H22+'Capital & Debt'!H24+'Capital & Debt'!H25 -> 401592.17 | I24: =I27*MIN(MAX(0,pf_ltv_limit*'Asset Register'!H61-'Capital & Debt'!H43-'Capital & Debt'!H50),MAX(0,pf_max_raise-'Capital & Debt'!H38))+MAX(0,'Financial Statements'!H65-MAX('Capital & Debt'!H60,min_cash_buffer))+'Capital & Debt'!I14+'Capital & Debt'!I22+'Capital & Debt'!I24+'Capital & Debt'!I25 -> 398137.69 | J24: =J27*MIN(MAX(0,pf_ltv_limit*'Asset Register'!I61-'Capital & Debt'!I43-'Capital & Debt'!I50),MAX(0,pf_max_raise-'Capital & Debt'!I38))+MAX(0,'Financial Statements'!I65-MAX('Capital & Debt'!I60,min_cash_buffer))+'Capital & Debt'!J14+'Capital & Debt'!J22+'Capital & Debt'!J24+'Capital & Debt'!J25 -> 386348.09 | K24: =K27*MIN(MAX(0,pf_ltv_limit*'Asset Register'!J61-'Capital & Debt'!J43-'Capital & Debt'!J50),MAX(0,pf_max_raise-'Capital & Debt'!J38))+MAX(0,'Financial Statements'!J65-MAX('Capital & Debt'!J60,min_cash_buffer))+'Capital & Debt'!K14+'Capital & Debt'!K22+'Capital & Debt'!K24+'Capital & Debt'!K25 -> 365119.02 | ... BA24: =BA27*MIN(MAX(0,pf_ltv_limit*'Asset Register'!AZ61-'Capital & Debt'!AZ43-'Capital & Debt'!AZ50),MAX(0,pf_max_raise-'Capital & Debt'!AZ38))+MAX(0,'Financial Statements'!AZ65-MAX('Capital & Debt'!AZ60,min_cash_buffer))+'Capital & Debt'!BA14+'Capital & Debt'!BA22+'Capital & Debt'!BA24+'Capital & Debt'!BA25 -> 2949244.1
A25: Affordable properties | B25: properties | D25: =IF(constrain_growth=1,MAX(0,INT(D24/(D23*IF(D27=1,MAX(0.01,1-pf_ltv_limit),1)))),999999) -> 3 | E25: =IF(constrain_growth=1,MAX(0,INT(E24/(E23*IF(E27=1,MAX(0.01,1-pf_ltv_limit),1)))),999999) -> 3 | F25: =IF(constrain_growth=1,MAX(0,INT(F24/(F23*IF(F27=1,MAX(0.01,1-pf_ltv_limit),1)))),999999) -> 4 | G25: =IF(constrain_growth=1,MAX(0,INT(G24/(G23*IF(G27=1,MAX(0.01,1-pf_ltv_limit),1)))),999999) -> 4 | H25: =IF(constrain_growth=1,MAX(0,INT(H24/(H23*IF(H27=1,MAX(0.01,1-pf_ltv_limit),1)))),999999) -> 4 | I25: =IF(constrain_growth=1,MAX(0,INT(I24/(I23*IF(I27=1,MAX(0.01,1-pf_ltv_limit),1)))),999999) -> 3 | J25: =IF(constrain_growth=1,MAX(0,INT(J24/(J23*IF(J27=1,MAX(0.01,1-pf_ltv_limit),1)))),999999) -> 3 | K25: =IF(constrain_growth=1,MAX(0,INT(K24/(K23*IF(K27=1,MAX(0.01,1-pf_ltv_limit),1)))),999999) -> 3 | ... BA25: =IF(constrain_growth=1,MAX(0,INT(BA24/(BA23*IF(BA27=1,MAX(0.01,1-pf_ltv_limit),1)))),999999) -> 1
A26: Growth-curve acquisitions (unconstrained) | B26: properties | D26: =IF(D$6<=3,CHOOSE(D$6,acq_year1,acq_year2,acq_year3),MIN(MAX(logistic_floor,IF(D$6>=logistic_start_yr,ROUND($C$4*D9*(1-D9/logistic_ceiling),0),0)),MAX(0,logistic_ceiling-D9))) -> 1 | E26: =IF(E$6<=3,CHOOSE(E$6,acq_year1,acq_year2,acq_year3),MIN(MAX(logistic_floor,IF(E$6>=logistic_start_yr,ROUND($C$4*E9*(1-E9/logistic_ceiling),0),0)),MAX(0,logistic_ceiling-E9))) -> 2 | F26: =IF(F$6<=3,CHOOSE(F$6,acq_year1,acq_year2,acq_year3),MIN(MAX(logistic_floor,IF(F$6>=logistic_start_yr,ROUND($C$4*F9*(1-F9/logistic_ceiling),0),0)),MAX(0,logistic_ceiling-F9))) -> 3 | G26: =IF(G$6<=3,CHOOSE(G$6,acq_year1,acq_year2,acq_year3),MIN(MAX(logistic_floor,IF(G$6>=logistic_start_yr,ROUND($C$4*G9*(1-G9/logistic_ceiling),0),0)),MAX(0,logistic_ceiling-G9))) -> 3 | H26: =IF(H$6<=3,CHOOSE(H$6,acq_year1,acq_year2,acq_year3),MIN(MAX(logistic_floor,IF(H$6>=logistic_start_yr,ROUND($C$4*H9*(1-H9/logistic_ceiling),0),0)),MAX(0,logistic_ceiling-H9))) -> 3 | I26: =IF(I$6<=3,CHOOSE(I$6,acq_year1,acq_year2,acq_year3),MIN(MAX(logistic_floor,IF(I$6>=logistic_start_yr,ROUND($C$4*I9*(1-I9/logistic_ceiling),0),0)),MAX(0,logistic_ceiling-I9))) -> 3 | J26: =IF(J$6<=3,CHOOSE(J$6,acq_year1,acq_year2,acq_year3),MIN(MAX(logistic_floor,IF(J$6>=logistic_start_yr,ROUND($C$4*J9*(1-J9/logistic_ceiling),0),0)),MAX(0,logistic_ceiling-J9))) -> 3 | K26: =IF(K$6<=3,CHOOSE(K$6,acq_year1,acq_year2,acq_year3),MIN(MAX(logistic_floor,IF(K$6>=logistic_start_yr,ROUND($C$4*K9*(1-K9/logistic_ceiling),0),0)),MAX(0,logistic_ceiling-K9))) -> 3 | ... BA26: =IF(BA$6<=3,CHOOSE(BA$6,acq_year1,acq_year2,acq_year3),MIN(MAX(logistic_floor,IF(BA$6>=logistic_start_yr,ROUND($C$4*BA9*(1-BA9/logistic_ceiling),0),0)),MAX(0,logistic_ceiling-BA9))) -> 6
A27: New Tontine capital available this year? (1 = Yes) | B27: 36526 | D27: =IF(AND(D$6<=pf_invest_phase_yrs,OR(pf_refi_toggle=0,D$6<pf_refi_year),'Capital & Debt'!C38<pf_max_raise),1,0) -> 1 | E27: =IF(AND(E$6<=pf_invest_phase_yrs,OR(pf_refi_toggle=0,E$6<pf_refi_year),'Capital & Debt'!D38<pf_max_raise),1,0) -> 1 | F27: =IF(AND(F$6<=pf_invest_phase_yrs,OR(pf_refi_toggle=0,F$6<pf_refi_year),'Capital & Debt'!E38<pf_max_raise),1,0) -> 1 | G27: =IF(AND(G$6<=pf_invest_phase_yrs,OR(pf_refi_toggle=0,G$6<pf_refi_year),'Capital & Debt'!F38<pf_max_raise),1,0) -> 1 | H27: =IF(AND(H$6<=pf_invest_phase_yrs,OR(pf_refi_toggle=0,H$6<pf_refi_year),'Capital & Debt'!G38<pf_max_raise),1,0) -> 1 | I27: =IF(AND(I$6<=pf_invest_phase_yrs,OR(pf_refi_toggle=0,I$6<pf_refi_year),'Capital & Debt'!H38<pf_max_raise),1,0) -> 1 | J27: =IF(AND(J$6<=pf_invest_phase_yrs,OR(pf_refi_toggle=0,J$6<pf_refi_year),'Capital & Debt'!I38<pf_max_raise),1,0) -> 1 | K27: =IF(AND(K$6<=pf_invest_phase_yrs,OR(pf_refi_toggle=0,K$6<pf_refi_year),'Capital & Debt'!J38<pf_max_raise),1,0) -> 1 | ... BA27: =IF(AND(BA$6<=pf_invest_phase_yrs,OR(pf_refi_toggle=0,BA$6<pf_refi_year),'Capital & Debt'!AZ38<pf_max_raise),1,0) -> 0

Sheet Capital & Debt
A1: CAPITAL & DEBT SCHEDULE
A2: Tontine (index-linked, interest-only) · Community shares (junior debt) · Bequests & gifts. Row 25 dividend rate is a per-year input.
A4: Tontine termination / refinancing year | B4: model year
A5: Commercial mortgage is amortised straight-line over its remaining term.
A6: Model year | D6: 1 | E6: 2 | F6: 3 | G6: 4 | H6: 5 | I6: 6 | J6: 7 | K6: 8 | L6: 9 | M6: 10 | N6: 11 | O6: 12 | P6: 13 | Q6: 14 | R6: 15 | S6: 16 | T6: 17 | U6: 18 | V6: 19 | W6: 20 | X6: 21 | Y6: 22 | Z6: 23 | AA6: 24 | AB6: 25 | AC6: 26 | AD6: 27 | AE6: 28 | AF6: 29 | AG6: 30 | AH6: 31 | AI6: 32 | AJ6: 33 | AK6: 34 | AL6: 35 | AM6: 36 | AN6: 37 | AO6: 38 | AP6: 39 | AQ6: 40 | AR6: 41 | AS6: 42 | AT6: 43 | AU6: 44 | AV6: 45 | AW6: 46 | AX6: 47 | AY6: 48 | AZ6: 49 | BA6: 50
A7: Calendar year | D7: =base_calendar_year+D$6-1 -> 2026 | E7: =base_calendar_year+E$6-1 -> 2027 | F7: =base_calendar_year+F$6-1 -> 2028 | G7: =base_calendar_year+G$6-1 -> 2029 | H7: =base_calendar_year+H$6-1 -> 2030 | I7: =base_calendar_year+I$6-1 -> 2031 | J7: =base_calendar_year+J$6-1 -> 2032 | K7: =base_calendar_year+K$6-1 -> 2033 | ... BA7: =base_calendar_year+BA$6-1 -> 2075
A9: BEQUESTS & GIFTS
A10: Cash gifts from living donors | B10: £ | D10: =gift_baseline*(1+beq_growth_mult)^(D$6-1)*'Macro & Indexation'!D$20 -> 40000 | E10: =gift_baseline*(1+beq_growth_mult)^(E$6-1)*'Macro & Indexation'!E$20 -> 41000 | F10: =gift_baseline*(1+beq_growth_mult)^(F$6-1)*'Macro & Indexation'!F$20 -> 42025 | G10: =gift_baseline*(1+beq_growth_mult)^(G$6-1)*'Macro & Indexation'!G$20 -> 43075.625 | H10: =gift_baseline*(1+beq_growth_mult)^(H$6-1)*'Macro & Indexation'!H$20 -> 44152.516 | I10: =gift_baseline*(1+beq_growth_mult)^(I$6-1)*'Macro & Indexation'!I$20 -> 45256.329 | J10: =gift_baseline*(1+beq_growth_mult)^(J$6-1)*'Macro & Indexation'!J$20 -> 46387.737 | K10: =gift_baseline*(1+beq_growth_mult)^(K$6-1)*'Macro & Indexation'!K$20 -> 47547.43 | ... BA10: =gift_baseline*(1+beq_growth_mult)^(BA$6-1)*'Macro & Indexation'!BA$20 -> 134131.07
A11: Bequests from estates | B11: £ | D11: =beq_baseline*(1+beq_growth_mult)^(D$6-1)*'Macro & Indexation'!D$20 -> 60000 | E11: =beq_baseline*(1+beq_growth_mult)^(E$6-1)*'Macro & Indexation'!E$20 -> 61500 | F11: =beq_baseline*(1+beq_growth_mult)^(F$6-1)*'Macro & Indexation'!F$20 -> 63037.5 | G11: =beq_baseline*(1+beq_growth_mult)^(G$6-1)*'Macro & Indexation'!G$20 -> 64613.437 | H11: =beq_baseline*(1+beq_growth_mult)^(H$6-1)*'Macro & Indexation'!H$20 -> 66228.773 | I11: =beq_baseline*(1+beq_growth_mult)^(I$6-1)*'Macro & Indexation'!I$20 -> 67884.493 | J11: =beq_baseline*(1+beq_growth_mult)^(J$6-1)*'Macro & Indexation'!J$20 -> 69581.605 | K11: =beq_baseline*(1+beq_growth_mult)^(K$6-1)*'Macro & Indexation'!K$20 -> 71321.145 | ... BA11: =beq_baseline*(1+beq_growth_mult)^(BA$6-1)*'Macro & Indexation'!BA$20 -> 201196.61
A12: Founding capital injection | B12: £ | D12: =IF(D$6=1,founding_capital,0) -> 150000 | E12: =IF(E$6=1,founding_capital,0) -> 0 | F12: =IF(F$6=1,founding_capital,0) -> 0 | G12: =IF(G$6=1,founding_capital,0) -> 0 | H12: =IF(H$6=1,founding_capital,0) -> 0 | I12: =IF(I$6=1,founding_capital,0) -> 0 | J12: =IF(J$6=1,founding_capital,0) -> 0 | K12: =IF(K$6=1,founding_capital,0) -> 0 | ... BA12: =IF(BA$6=1,founding_capital,0) -> 0
A13: Gift Aid recovery | B13: £ | D13: =IF(gift_aid_toggle=1,D10*gift_aid_rate,0) -> 10000 | E13: =IF(gift_aid_toggle=1,E10*gift_aid_rate,0) -> 10250 | F13: =IF(gift_aid_toggle=1,F10*gift_aid_rate,0) -> 10506.25 | G13: =IF(gift_aid_toggle=1,G10*gift_aid_rate,0) -> 10768.906 | H13: =IF(gift_aid_toggle=1,H10*gift_aid_rate,0) -> 11038.129 | I13: =IF(gift_aid_toggle=1,I10*gift_aid_rate,0) -> 11314.082 | J13: =IF(gift_aid_toggle=1,J10*gift_aid_rate,0) -> 11596.934 | K13: =IF(gift_aid_toggle=1,K10*gift_aid_rate,0) -> 11886.858 | ... BA13: =IF(gift_aid_toggle=1,BA10*gift_aid_rate,0) -> 33532.768
A14: Total gift income | B14: £ | D14: =SUM(D10:D13) -> 260000 | E14: =SUM(E10:E13) -> 112750 | F14: =SUM(F10:F13) -> 115568.75 | G14: =SUM(G10:G13) -> 118457.97 | H14: =SUM(H10:H13) -> 121419.42 | I14: =SUM(I10:I13) -> 124454.9 | J14: =SUM(J10:J13) -> 127566.28 | K14: =SUM(K10:K13) -> 130755.43 | ... BA14: =SUM(BA10:BA13) -> 368860.45
A15: Cumulative gifts, bequests & founding capital | B15: £ | D15: =D14 -> 260000 | E15: =D15+E14 -> 372750 | F15: =E15+F14 -> 488318.75 | G15: =F15+G14 -> 606776.72 | H15: =G15+H14 -> 728196.14 | I15: =H15+I14 -> 852651.04 | J15: =I15+J14 -> 980217.32 | K15: =J15+K14 -> 1110972.7 | L15: =K15+L14 -> 1244997.1 | ... BA15: =AZ15+BA14 -> 10873278
A17: COMMUNITY SHARES (JUNIOR DEBT)
A18: Target issuance (indexed) | B18: £ | D18: =cs_baseline_issue*cs_takeup_mult*'Macro & Indexation'!D$20 -> 250000 | E18: =cs_baseline_issue*cs_takeup_mult*'Macro & Indexation'!E$20 -> 256250 | F18: =cs_baseline_issue*cs_takeup_mult*'Macro & Indexation'!F$20 -> 262656.25 | G18: =cs_baseline_issue*cs_takeup_mult*'Macro & Indexation'!G$20 -> 269222.66 | H18: =cs_baseline_issue*cs_takeup_mult*'Macro & Indexation'!H$20 -> 275953.22 | I18: =cs_baseline_issue*cs_takeup_mult*'Macro & Indexation'!I$20 -> 282852.05 | J18: =cs_baseline_issue*cs_takeup_mult*'Macro & Indexation'!J$20 -> 289923.35 | K18: =cs_baseline_issue*cs_takeup_mult*'Macro & Indexation'!K$20 -> 297171.44 | ... BA18: =cs_baseline_issue*cs_takeup_mult*'Macro & Indexation'!BA$20 -> 838319.2
A19: Other capital — opening (total capital ex-shares) | B19: £ | D19: =0 -> 0 | E19: ='Financial Statements'!D44-D26 -> 307624.38 | F19: ='Financial Statements'!E44-E26 -> 821883.17 | G19: ='Financial Statements'!F44-F26 -> 1613096.2 | H19: ='Financial Statements'!G44-G26 -> 2392236.7 | I19: ='Financial Statements'!H44-H26 -> 3260995.8 | J19: ='Financial Statements'!I44-I26 -> 4186101.2 | K19: ='Financial Statements'!J44-J26 -> 5184045.5 | L19: ='Financial Statements'!K44-K26 -> 6203511 | ... BA19: ='Financial Statements'!AZ44-AZ26 -> 61377604
A20: Maximum share capital permitted | B20: cap % of total capital | D20: =cs_max_pct_capital/(1-cs_max_pct_capital)*D19 -> 0 | E20: =cs_max_pct_capital/(1-cs_max_pct_capital)*E19 -> 76906.094 | F20: =cs_max_pct_capital/(1-cs_max_pct_capital)*F19 -> 205470.79 | G20: =cs_max_pct_capital/(1-cs_max_pct_capital)*G19 -> 403274.05 | H20: =cs_max_pct_capital/(1-cs_max_pct_capital)*H19 -> 598059.18 | I20: =cs_max_pct_capital/(1-cs_max_pct_capital)*I19 -> 815248.94 | J20: =cs_max_pct_capital/(1-cs_max_pct_capital)*J19 -> 1046525.3 | K20: =cs_max_pct_capital/(1-cs_max_pct_capital)*K19 -> 1296011.4 | ... BA20: =cs_max_pct_capital/(1-cs_max_pct_capital)*BA19 -> 15344401
A21: Opening share capital | B21: £ | D21: =0 -> 0 | E21: =D26 -> 0 | F21: =E26 -> 76906.094 | G21: =F26 -> 205470.79 | H21: =G26 -> 403274.05 | I21: =H26 -> 598059.18 | J21: =I26 -> 815248.94 | K21: =J26 -> 1044987.2 | L21: =K26 -> 1291902 | ... BA21: =AZ26 -> 13288451
A22: Shares issued | B22: £ | D22: =MIN(D18,MAX(0,D20-D21)) -> 0 | E22: =MIN(E18,MAX(0,E20-E21)) -> 76906.094 | F22: =MIN(F18,MAX(0,F20-F21)) -> 128564.7 | G22: =MIN(G18,MAX(0,G20-G21)) -> 197803.25 | H22: =MIN(H18,MAX(0,H20-H21)) -> 194785.14 | I22: =MIN(I18,MAX(0,I20-I21)) -> 217189.76 | J22: =MIN(J18,MAX(0,J20-J21)) -> 231276.35 | K22: =MIN(K18,MAX(0,K20-K21)) -> 251024.22 | ... BA22: =MIN(BA18,MAX(0,BA20-BA21)) -> 838319.2
A23: Shares eligible for withdrawal | B23: £ | D23: =IF(D$6-MAX(1,cs_withdrawal_years)<1,0,OFFSET($D$26,0,D$6-1-MAX(1,cs_withdrawal_years))) -> 0 | E23: =IF(E$6-MAX(1,cs_withdrawal_years)<1,0,OFFSET($D$26,0,E$6-1-MAX(1,cs_withdrawal_years))) -> 0 | F23: =IF(F$6-MAX(1,cs_withdrawal_years)<1,0,OFFSET($D$26,0,F$6-1-MAX(1,cs_withdrawal_years))) -> 0 | G23: =IF(G$6-MAX(1,cs_withdrawal_years)<1,0,OFFSET($D$26,0,G$6-1-MAX(1,cs_withdrawal_years))) -> 0 | H23: =IF(H$6-MAX(1,cs_withdrawal_years)<1,0,OFFSET($D$26,0,H$6-1-MAX(1,cs_withdrawal_years))) -> 0 | I23: =IF(I$6-MAX(1,cs_withdrawal_years)<1,0,OFFSET($D$26,0,I$6-1-MAX(1,cs_withdrawal_years))) -> 0 | J23: =IF(J$6-MAX(1,cs_withdrawal_years)<1,0,OFFSET($D$26,0,J$6-1-MAX(1,cs_withdrawal_years))) -> 76906.094 | K23: =IF(K$6-MAX(1,cs_withdrawal_years)<1,0,OFFSET($D$26,0,K$6-1-MAX(1,cs_withdrawal_years))) -> 205470.79 | ... BA23: =IF(BA$6-MAX(1,cs_withdrawal_years)<1,0,OFFSET($D$26,0,BA$6-1-MAX(1,cs_withdrawal_years))) -> 10892580
A24: Withdrawals | B24: £ | D24: =-MIN(D21,D23*cs_withdrawal_rate) -> 0 | E24: =-MIN(E21,E23*cs_withdrawal_rate) -> 0 | F24: =-MIN(F21,F23*cs_withdrawal_rate) -> 0 | G24: =-MIN(G21,G23*cs_withdrawal_rate) -> 0 | H24: =-MIN(H21,H23*cs_withdrawal_rate) -> 0 | I24: =-MIN(I21,I23*cs_withdrawal_rate) -> 0 | J24: =-MIN(J21,J23*cs_withdrawal_rate) -> -1538.1219 | K24: =-MIN(K21,K23*cs_withdrawal_rate) -> -4109.4158 | ... BA24: =-MIN(BA21,BA23*cs_withdrawal_rate) -> -217851.61
A25: Issuance / marketing costs | B25: £ | D25: =-D22*cs_issue_cost_pct -> 0 | E25: =-E22*cs_issue_cost_pct -> -3845.3047 | F25: =-F22*cs_issue_cost_pct -> -6428.2349 | G25: =-G22*cs_issue_cost_pct -> -9890.1627 | H25: =-H22*cs_issue_cost_pct -> -9739.2569 | I25: =-I22*cs_issue_cost_pct -> -10859.488 | J25: =-J22*cs_issue_cost_pct -> -11563.817 | K25: =-K22*cs_issue_cost_pct -> -12551.211 | ... BA25: =-BA22*cs_issue_cost_pct -> -41915.96
A26: Closing share capital | B26: £ | D26: =D21+D22+D24 -> 0 | E26: =E21+E22+E24 -> 76906.094 | F26: =F21+F22+F24 -> 205470.79 | G26: =G21+G22+G24 -> 403274.05 | H26: =H21+H22+H24 -> 598059.18 | I26: =I21+I22+I24 -> 815248.94 | J26: =J21+J22+J24 -> 1044987.2 | K26: =K21+K22+K24 -> 1291902 | ... BA26: =BA21+BA22+BA24 -> 13908919
A27: Dividend rate — per year (INPUT) | B27: % p.a. | D27: =cs_dividend_rate -> 0.03 | E27: =cs_dividend_rate -> 0.03 | F27: =cs_dividend_rate -> 0.03 | G27: =cs_dividend_rate -> 0.03 | H27: =cs_dividend_rate -> 0.03 | I27: =cs_dividend_rate -> 0.03 | J27: =cs_dividend_rate -> 0.03 | K27: =cs_dividend_rate -> 0.03 | ... BA27: =cs_dividend_rate -> 0.03
A28: Dividends payable (capped by surplus) | B28: £ | D28: =MIN(D21*D27,MAX(0,'Financial Statements'!D23)) -> 0 | E28: =MIN(E21*E27,MAX(0,'Financial Statements'!E23)) -> 0 | F28: =MIN(F21*F27,MAX(0,'Financial Statements'!F23)) -> 2307.1828 | G28: =MIN(G21*G27,MAX(0,'Financial Statements'!G23)) -> 6164.1238 | H28: =MIN(H21*H27,MAX(0,'Financial Statements'!H23)) -> 1278.9368 | I28: =MIN(I21*I27,MAX(0,'Financial Statements'!I23)) -> 0 | J28: =MIN(J21*J27,MAX(0,'Financial Statements'!J23)) -> 0 | K28: =MIN(K21*K27,MAX(0,'Financial Statements'!K23)) -> 0 | ... BA28: =MIN(BA21*BA27,MAX(0,'Financial Statements'!BA23)) -> 398653.54
A29: TONTINE FUND — CLOSED-END LIFETIME ANNUITY MUTUAL
A30: Opening balance | B30: £ | D30: =0 -> 0 | E30: =D43 -> 53300 | F30: =E43 -> 465436.71 | G30: =F43 -> 1165357 | H30: =G43 -> 1860651.5 | I30: =H43 -> 2631621.6 | J30: =I43 -> 3451190.3 | K30: =J43 -> 4336812.8 | L30: =K43 -> 5236701.4 | ... BA30: =AZ43 -> 4022629.9
A31: CPI indexation uplift on principal | B31: £ | D31: =D30*'Macro & Indexation'!D$9 -> 0 | E31: =E30*'Macro & Indexation'!E$9 -> 1332.5 | F31: =F30*'Macro & Indexation'!F$9 -> 11635.918 | G31: =G30*'Macro & Indexation'!G$9 -> 29133.924 | H31: =H30*'Macro & Indexation'!H$9 -> 46516.286 | I31: =I30*'Macro & Indexation'!I$9 -> 65790.54 | J31: =J30*'Macro & Indexation'!J$9 -> 86279.758 | K31: =K30*'Macro & Indexation'!K$9 -> 108420.32 | ... BA31: =BA30*'Macro & Indexation'!BA$9 -> 100565.75
A32: Indexed opening balance | B32: £ | D32: =D30+D31 -> 0 | E32: =E30+E31 -> 54632.5 | F32: =F30+F31 -> 477072.63 | G32: =G30+G31 -> 1194490.9 | H32: =H30+H31 -> 1907167.7 | I32: =I30+I31 -> 2697412.1 | J32: =J30+J31 -> 3537470.1 | K32: =K30+K31 -> 4445233.1 | ... BA32: =BA30+BA31 -> 4123195.6
A33: Cumulative capital raised — opening | B33: £ | D33: =0 -> 0 | E33: =D38 -> 53300 | F33: =E38 -> 464104.21 | G33: =F38 -> 1152388.6 | H33: =G38 -> 1818549.1 | I33: =H38 -> 2543003 | J33: =I38 -> 3296781.2 | K33: =J38 -> 4096123.9 | L33: =K38 -> 4887592.2 | ... BA33: =AZ38 -> 6577569.3
A34: Remaining raise capacity | B34: £ | D34: =MAX(0,pf_max_raise-D33) -> 50000000 | E34: =MAX(0,pf_max_raise-E33) -> 49946700 | F34: =MAX(0,pf_max_raise-F33) -> 49535896 | G34: =MAX(0,pf_max_raise-G33) -> 48847611 | H34: =MAX(0,pf_max_raise-H33) -> 48181451 | I34: =MAX(0,pf_max_raise-I33) -> 47456997 | J34: =MAX(0,pf_max_raise-J33) -> 46703219 | K34: =MAX(0,pf_max_raise-K33) -> 45903876 | ... BA34: =MAX(0,pf_max_raise-BA33) -> 43422431
A35: LTV headroom | B35: £ | D35: =MAX(0,pf_ltv_limit*'Asset Register'!D61-D32-D46) -> 196000 | E35: =MAX(0,pf_ltv_limit*'Asset Register'!E61-E32-E46) -> 553947.5 | F35: =MAX(0,pf_ltv_limit*'Asset Register'!F61-F32-F46) -> 782687.97 | G35: =MAX(0,pf_ltv_limit*'Asset Register'!G61-G32-G46) -> 761287.43 | H35: =MAX(0,pf_ltv_limit*'Asset Register'!H61-H32-H46) -> 791806.35 | I35: =MAX(0,pf_ltv_limit*'Asset Register'!I61-I32-I46) -> 794385.61 | J35: =MAX(0,pf_ltv_limit*'Asset Register'!J61-J32-J46) -> 799342.69 | K35: =MAX(0,pf_ltv_limit*'Asset Register'!K61-K32-K46) -> 791468.33 | ... BA35: =MAX(0,pf_ltv_limit*'Asset Register'!BA61-BA32-BA46) -> 47700609
A36: Funding requirement | B36: £ | D36: =MAX(0,'Asset Register'!D128-D14-(D22+D24+D25)+MAX(0,MAX(C60,min_cash_buffer)-'Financial Statements'!C65)) -> 53300 | E36: =MAX(0,'Asset Register'!E128-E14-(E22+E24+E25)+MAX(0,MAX(D60,min_cash_buffer)-'Financial Statements'!D65)) -> 410804.21 | F36: =MAX(0,'Asset Register'!F128-F14-(F22+F24+F25)+MAX(0,MAX(E60,min_cash_buffer)-'Financial Statements'!E65)) -> 688284.35 | G36: =MAX(0,'Asset Register'!G128-G14-(G22+G24+G25)+MAX(0,MAX(F60,min_cash_buffer)-'Financial Statements'!F65)) -> 666160.56 | H36: =MAX(0,'Asset Register'!H128-H14-(H22+H24+H25)+MAX(0,MAX(G60,min_cash_buffer)-'Financial Statements'!G65)) -> 724453.84 | I36: =MAX(0,'Asset Register'!I128-I14-(I22+I24+I25)+MAX(0,MAX(H60,min_cash_buffer)-'Financial Statements'!H65)) -> 753778.21 | J36: =MAX(0,'Asset Register'!J128-J14-(J22+J24+J25)+MAX(0,MAX(I60,min_cash_buffer)-'Financial Statements'!I65)) -> 800515.78 | K36: =MAX(0,'Asset Register'!K128-K14-(K22+K24+K25)+MAX(0,MAX(J60,min_cash_buffer)-'Financial Statements'!J65)) -> 842662.63 | ... BA36: =MAX(0,'Asset Register'!BA128-BA14-(BA22+BA24+BA25)+MAX(0,MAX(AZ60,min_cash_buffer)-'Financial Statements'!AZ65)) -> 591318.2
A37: Drawdown | B37: £ | D37: =IF(AND(D$6<=pf_invest_phase_yrs,OR(pf_refi_toggle=0,D$6<pf_refi_year)),MIN(D36,D35,D34),0) -> 53300 | E37: =IF(AND(E$6<=pf_invest_phase_yrs,OR(pf_refi_toggle=0,E$6<pf_refi_year)),MIN(E36,E35,E34),0) -> 410804.21 | F37: =IF(AND(F$6<=pf_invest_phase_yrs,OR(pf_refi_toggle=0,F$6<pf_refi_year)),MIN(F36,F35,F34),0) -> 688284.35 | G37: =IF(AND(G$6<=pf_invest_phase_yrs,OR(pf_refi_toggle=0,G$6<pf_refi_year)),MIN(G36,G35,G34),0) -> 666160.56 | H37: =IF(AND(H$6<=pf_invest_phase_yrs,OR(pf_refi_toggle=0,H$6<pf_refi_year)),MIN(H36,H35,H34),0) -> 724453.84 | I37: =IF(AND(I$6<=pf_invest_phase_yrs,OR(pf_refi_toggle=0,I$6<pf_refi_year)),MIN(I36,I35,I34),0) -> 753778.21 | J37: =IF(AND(J$6<=pf_invest_phase_yrs,OR(pf_refi_toggle=0,J$6<pf_refi_year)),MIN(J36,J35,J34),0) -> 799342.69 | K37: =IF(AND(K$6<=pf_invest_phase_yrs,OR(pf_refi_toggle=0,K$6<pf_refi_year)),MIN(K36,K35,K34),0) -> 791468.33 | ... BA37: =IF(AND(BA$6<=pf_invest_phase_yrs,OR(pf_refi_toggle=0,BA$6<pf_refi_year)),MIN(BA36,BA35,BA34),0) -> 0
A38: Cumulative capital raised — closing | B38: £ | D38: =D33+D37 -> 53300 | E38: =E33+E37 -> 464104.21 | F38: =F33+F37 -> 1152388.6 | G38: =G33+G37 -> 1818549.1 | H38: =H33+H37 -> 2543003 | I38: =I33+I37 -> 3296781.2 | J38: =J33+J37 -> 4096123.9 | K38: =K33+K37 -> 4887592.2 | ... BA38: =BA33+BA37 -> 6577569.3
A39: Implied SLC coupon rate (index + spread) | B39: % p.a. | D39: ='Macro & Indexation'!D$9+pf_coupon_spread -> 0.0625 | E39: ='Macro & Indexation'!E$9+pf_coupon_spread -> 0.0625 | F39: ='Macro & Indexation'!F$9+pf_coupon_spread -> 0.0625 | G39: ='Macro & Indexation'!G$9+pf_coupon_spread -> 0.0625 | H39: ='Macro & Indexation'!H$9+pf_coupon_spread -> 0.0625 | I39: ='Macro & Indexation'!I$9+pf_coupon_spread -> 0.0625 | J39: ='Macro & Indexation'!J$9+pf_coupon_spread -> 0.0625 | K39: ='Macro & Indexation'!K$9+pf_coupon_spread -> 0.0625 | ... BA39: ='Macro & Indexation'!BA$9+pf_coupon_spread -> 0.0625
A40: Interest paid | B40: £ | D40: =-(D32+D37/2)*D39 -> -1665.625 | E40: =-(E32+E37/2)*E39 -> -16252.163 | F40: =-(F32+F37/2)*F39 -> -51325.925 | G40: =-(G32+G37/2)*G39 -> -95473.199 | H40: =-(H32+H37/2)*H39 -> -141837.17 | I40: =-(I32+I37/2)*I39 -> -192143.83 | J40: =-(J32+J37/2)*J39 -> -246071.34 | K40: =-(K32+K37/2)*K39 -> -302560.45 | ... BA40: =-(BA32+BA37/2)*BA39 -> -257699.73
A41: Progressive release to SLC reserves | B41: £ | D41: =-IF(D$6>=pf_release_start_yr,(D32+D37)*pf_release_rate,0) -> 0 | E41: =-IF(E$6>=pf_release_start_yr,(E32+E37)*pf_release_rate,0) -> 0 | F41: =-IF(F$6>=pf_release_start_yr,(F32+F37)*pf_release_rate,0) -> 0 | G41: =-IF(G$6>=pf_release_start_yr,(G32+G37)*pf_release_rate,0) -> 0 | H41: =-IF(H$6>=pf_release_start_yr,(H32+H37)*pf_release_rate,0) -> 0 | I41: =-IF(I$6>=pf_release_start_yr,(I32+I37)*pf_release_rate,0) -> 0 | J41: =-IF(J$6>=pf_release_start_yr,(J32+J37)*pf_release_rate,0) -> 0 | K41: =-IF(K$6>=pf_release_start_yr,(K32+K37)*pf_release_rate,0) -> 0 | ... BA41: =-IF(BA$6>=pf_release_start_yr,(BA32+BA37)*pf_release_rate,0) -> -247391.74
A42: Transferred to commercial mortgage (refinancing) | B42: £ | D42: =IF(AND(pf_refi_toggle=1,D$6=pf_refi_year),-(D32+D37+D41),0) -> 0 | E42: =IF(AND(pf_refi_toggle=1,E$6=pf_refi_year),-(E32+E37+E41),0) -> 0 | F42: =IF(AND(pf_refi_toggle=1,F$6=pf_refi_year),-(F32+F37+F41),0) -> 0 | G42: =IF(AND(pf_refi_toggle=1,G$6=pf_refi_year),-(G32+G37+G41),0) -> 0 | H42: =IF(AND(pf_refi_toggle=1,H$6=pf_refi_year),-(H32+H37+H41),0) -> 0 | I42: =IF(AND(pf_refi_toggle=1,I$6=pf_refi_year),-(I32+I37+I41),0) -> 0 | J42: =IF(AND(pf_refi_toggle=1,J$6=pf_refi_year),-(J32+J37+J41),0) -> 0 | K42: =IF(AND(pf_refi_toggle=1,K$6=pf_refi_year),-(K32+K37+K41),0) -> 0 | ... BA42: =IF(AND(pf_refi_toggle=1,BA$6=pf_refi_year),-(BA32+BA37+BA41),0) -> 0
A43: Closing balance | B43: £ | D43: =D32+D37+D41+D42 -> 53300 | E43: =E32+E37+E41+E42 -> 465436.71 | F43: =F32+F37+F41+F42 -> 1165357 | G43: =G32+G37+G41+G42 -> 1860651.5 | H43: =H32+H37+H41+H42 -> 2631621.6 | I43: =I32+I37+I41+I42 -> 3451190.3 | J43: =J32+J37+J41+J42 -> 4336812.8 | K43: =K32+K37+K41+K42 -> 5236701.4 | ... BA43: =BA32+BA37+BA41+BA42 -> 3875803.9
...

Sheet Asset Register
A1: PROPERTY PORTFOLIO — ASSET REGISTER
A2: Each acquisition year is tracked as its own cohort. Values grow with HPI; cohort rents grow with rent inflation from the purchase-year rent.
A6: Model year | D6: 1 | E6: 2 | F6: 3 | G6: 4 | H6: 5 | I6: 6 | J6: 7 | K6: 8 | L6: 9 | M6: 10 | N6: 11 | O6: 12 | P6: 13 | Q6: 14 | R6: 15 | S6: 16 | T6: 17 | U6: 18 | V6: 19 | W6: 20 | X6: 21 | Y6: 22 | Z6: 23 | AA6: 24 | AB6: 25 | AC6: 26 | AD6: 27 | AE6: 28 | AF6: 29 | AG6: 30 | AH6: 31 | AI6: 32 | AJ6: 33 | AK6: 34 | AL6: 35 | AM6: 36 | AN6: 37 | AO6: 38 | AP6: 39 | AQ6: 40 | AR6: 41 | AS6: 42 | AT6: 43 | AU6: 44 | AV6: 45 | AW6: 46 | AX6: 47 | AY6: 48 | AZ6: 49 | BA6: 50
A7: Calendar year | D7: =base_calendar_year+D$6-1 -> 2026 | E7: =base_calendar_year+E$6-1 -> 2027 | F7: =base_calendar_year+F$6-1 -> 2028 | G7: =base_calendar_year+G$6-1 -> 2029 | H7: =base_calendar_year+H$6-1 -> 2030 | I7: =base_calendar_year+I$6-1 -> 2031 | J7: =base_calendar_year+J$6-1 -> 2032 | K7: =base_calendar_year+K$6-1 -> 2033 | ... BA7: =base_calendar_year+BA$6-1 -> 2075
A9: COHORT PORTFOLIO VALUE (£, HPI-indexed)
A10: Cohort — Year 1 | B10: 1 | D10: =IF(D$6<$B10,0,IF(D$6=$B10,'Growth Engine'!D$10*'Macro & Indexation'!D$19,C10*(1+'Macro & Indexation'!D$16))) -> 280000 | E10: =IF(E$6<$B10,0,IF(E$6=$B10,'Growth Engine'!E$10*'Macro & Indexation'!E$19,D10*(1+'Macro & Indexation'!E$16))) -> 289800 | F10: =IF(F$6<$B10,0,IF(F$6=$B10,'Growth Engine'!F$10*'Macro & Indexation'!F$19,E10*(1+'Macro & Indexation'!F$16))) -> 299943 | G10: =IF(G$6<$B10,0,IF(G$6=$B10,'Growth Engine'!G$10*'Macro & Indexation'!G$19,F10*(1+'Macro & Indexation'!G$16))) -> 310441.01 | H10: =IF(H$6<$B10,0,IF(H$6=$B10,'Growth Engine'!H$10*'Macro & Indexation'!H$19,G10*(1+'Macro & Indexation'!H$16))) -> 321306.44 | I10: =IF(I$6<$B10,0,IF(I$6=$B10,'Growth Engine'!I$10*'Macro & Indexation'!I$19,H10*(1+'Macro & Indexation'!I$16))) -> 332552.17 | J10: =IF(J$6<$B10,0,IF(J$6=$B10,'Growth Engine'!J$10*'Macro & Indexation'!J$19,I10*(1+'Macro & Indexation'!J$16))) -> 344191.49 | K10: =IF(K$6<$B10,0,IF(K$6=$B10,'Growth Engine'!K$10*'Macro & Indexation'!K$19,J10*(1+'Macro & Indexation'!K$16))) -> 356238.19 | ... BA10: =IF(BA$6<$B10,0,IF(BA$6=$B10,'Growth Engine'!BA$10*'Macro & Indexation'!BA$19,AZ10*(1+'Macro & Indexation'!BA$16))) -> 1510898.1
A11: Cohort — Year 2 | B11: 2 | D11: =IF(D$6<$B11,0,IF(D$6=$B11,'Growth Engine'!D$10*'Macro & Indexation'!D$19,C11*(1+'Macro & Indexation'!D$16))) -> 0 | E11: =IF(E$6<$B11,0,IF(E$6=$B11,'Growth Engine'!E$10*'Macro & Indexation'!E$19,D11*(1+'Macro & Indexation'!E$16))) -> 579600 | F11: =IF(F$6<$B11,0,IF(F$6=$B11,'Growth Engine'!F$10*'Macro & Indexation'!F$19,E11*(1+'Macro & Indexation'!F$16))) -> 599886 | G11: =IF(G$6<$B11,0,IF(G$6=$B11,'Growth Engine'!G$10*'Macro & Indexation'!G$19,F11*(1+'Macro & Indexation'!G$16))) -> 620882.01 | H11: =IF(H$6<$B11,0,IF(H$6=$B11,'Growth Engine'!H$10*'Macro & Indexation'!H$19,G11*(1+'Macro & Indexation'!H$16))) -> 642612.88 | I11: =IF(I$6<$B11,0,IF(I$6=$B11,'Growth Engine'!I$10*'Macro & Indexation'!I$19,H11*(1+'Macro & Indexation'!I$16))) -> 665104.33 | J11: =IF(J$6<$B11,0,IF(J$6=$B11,'Growth Engine'!J$10*'Macro & Indexation'!J$19,I11*(1+'Macro & Indexation'!J$16))) -> 688382.98 | K11: =IF(K$6<$B11,0,IF(K$6=$B11,'Growth Engine'!K$10*'Macro & Indexation'!K$19,J11*(1+'Macro & Indexation'!K$16))) -> 712476.39 | ... BA11: =IF(BA$6<$B11,0,IF(BA$6=$B11,'Growth Engine'!BA$10*'Macro & Indexation'!BA$19,AZ11*(1+'Macro & Indexation'!BA$16))) -> 3021796.2
A12: Cohort — Year 3 | B12: 3 | D12: =IF(D$6<$B12,0,IF(D$6=$B12,'Growth Engine'!D$10*'Macro & Indexation'!D$19,C12*(1+'Macro & Indexation'!D$16))) -> 0 | E12: =IF(E$6<$B12,0,IF(E$6=$B12,'Growth Engine'!E$10*'Macro & Indexation'!E$19,D12*(1+'Macro & Indexation'!E$16))) -> 0 | F12: =IF(F$6<$B12,0,IF(F$6=$B12,'Growth Engine'!F$10*'Macro & Indexation'!F$19,E12*(1+'Macro & Indexation'!F$16))) -> 899829 | G12: =IF(G$6<$B12,0,IF(G$6=$B12,'Growth Engine'!G$10*'Macro & Indexation'!G$19,F12*(1+'Macro & Indexation'!G$16))) -> 931323.01 | H12: =IF(H$6<$B12,0,IF(H$6=$B12,'Growth Engine'!H$10*'Macro & Indexation'!H$19,G12*(1+'Macro & Indexation'!H$16))) -> 963919.32 | I12: =IF(I$6<$B12,0,IF(I$6=$B12,'Growth Engine'!I$10*'Macro & Indexation'!I$19,H12*(1+'Macro & Indexation'!I$16))) -> 997656.5 | J12: =IF(J$6<$B12,0,IF(J$6=$B12,'Growth Engine'!J$10*'Macro & Indexation'!J$19,I12*(1+'Macro & Indexation'!J$16))) -> 1032574.5 | K12: =IF(K$6<$B12,0,IF(K$6=$B12,'Growth Engine'!K$10*'Macro & Indexation'!K$19,J12*(1+'Macro & Indexation'!K$16))) -> 1068714.6 | ... BA12: =IF(BA$6<$B12,0,IF(BA$6=$B12,'Growth Engine'!BA$10*'Macro & Indexation'!BA$19,AZ12*(1+'Macro & Indexation'!BA$16))) -> 4532694.3
A13: Cohort — Year 4 | B13: 4 | D13: =IF(D$6<$B13,0,IF(D$6=$B13,'Growth Engine'!D$10*'Macro & Indexation'!D$19,C13*(1+'Macro & Indexation'!D$16))) -> 0 | E13: =IF(E$6<$B13,0,IF(E$6=$B13,'Growth Engine'!E$10*'Macro & Indexation'!E$19,D13*(1+'Macro & Indexation'!E$16))) -> 0 | F13: =IF(F$6<$B13,0,IF(F$6=$B13,'Growth Engine'!F$10*'Macro & Indexation'!F$19,E13*(1+'Macro & Indexation'!F$16))) -> 0 | G13: =IF(G$6<$B13,0,IF(G$6=$B13,'Growth Engine'!G$10*'Macro & Indexation'!G$19,F13*(1+'Macro & Indexation'!G$16))) -> 931323.01 | H13: =IF(H$6<$B13,0,IF(H$6=$B13,'Growth Engine'!H$10*'Macro & Indexation'!H$19,G13*(1+'Macro & Indexation'!H$16))) -> 963919.32 | I13: =IF(I$6<$B13,0,IF(I$6=$B13,'Growth Engine'!I$10*'Macro & Indexation'!I$19,H13*(1+'Macro & Indexation'!I$16))) -> 997656.5 | J13: =IF(J$6<$B13,0,IF(J$6=$B13,'Growth Engine'!J$10*'Macro & Indexation'!J$19,I13*(1+'Macro & Indexation'!J$16))) -> 1032574.5 | K13: =IF(K$6<$B13,0,IF(K$6=$B13,'Growth Engine'!K$10*'Macro & Indexation'!K$19,J13*(1+'Macro & Indexation'!K$16))) -> 1068714.6 | ... BA13: =IF(BA$6<$B13,0,IF(BA$6=$B13,'Growth Engine'!BA$10*'Macro & Indexation'!BA$19,AZ13*(1+'Macro & Indexation'!BA$16))) -> 4532694.3
